Workbook

Sheet PL
B4: No | C4: Kode PL | D4: Profil Lulusan | E4: Deskripsi Kemampuan
B5: 1 | C5: PL.01 | D5: Mampu merancang, menganalisis, dan mengevaluasi sistem, infrastruktur, serta manajemen sumber daya air yang berkelanjutan berbasis teknologi dengan daya saing global | E5: - Perancang dan Analis Profesional – Mampu merancang, menganalisis, dan mengevaluasi sistem serta infrastruktur sumber daya air yang efisien, berkelanjutan, dan berbasis teknologi mutakhir.
E6: - Ahli Manajemen Sumber Daya Air – Menguasai prinsip manajemen sumber daya air terpadu untuk mendukung pengelolaan lingkungan dan pembangunan berkelanjutan.
E7: - Insinyur Berdaya Saing Global – Memiliki kompetensi teknis, adaptif terhadap inovasi, dan mampu bersaing di tingkat nasional maupun internasional dalam bidang pengairan.
B8: 2 | C8: PL.02 | D8: Memiliki pengetahuan dan keterampilan dalam perencanaan, desain, dan pengoperasian infrastruktur sumber daya air dengan daya saing global. | E8: - Perencana Infrastruktur Sumber Daya Air – Mampu menyusun rencana pengelolaan dan pengembangan infrastruktur sumber daya air yang efektif, efisien, dan berkelanjutan.
E9: - Perancang Sistem Pengairan – Menguasai prinsip dan teknik desain infrastruktur sumber daya air dengan penerapan teknologi modern untuk meningkatkan kinerja dan keandalan sistem.
E10: - Profesional Berdaya Saing Global – Siap berkontribusi di tingkat nasional dan internasional melalui kemampuan teknis, analitis, dan adaptif terhadap perkembangan teknologi dan kebutuhan global.
B11: 3 | C11: PL.03 | D11: Mampu menerapkan etika profesi dan nilai-nilai keislaman dengan menjunjung tinggi moralitas, tanggung jawab sosial, dan integritas demi pembangunan yang adil dan berkelanjutan yang berdaya saing global. | E11: - Profesional Beretika dan Berintegritas – Mampu menerapkan etika profesi serta menjunjung tinggi moralitas dan nilai-nilai keislaman dalam setiap aspek pekerjaan.
E12: - Individu Bertanggung Jawab Sosial – Berkomitmen terhadap tanggung jawab sosial dan berperan aktif dalam mewujudkan pembangunan yang adil dan berkelanjutan.
E13: - Insan Unggul Berdaya Saing Global – Memiliki karakter kuat, integritas tinggi, serta kemampuan adaptif untuk bersaing dan berkontribusi di tingkat nasional maupun internasional.
B14: 4 | C14: PL.04 | D14: Memiliki jiwa kewirausahaan di bidang pengairan serta mampu menjadi konsultan yang kompeten, mandiri, terpercaya, dan adaptif terhadap perubahan global serta kebutuhan masyarakat. | E14: - Wirausahawan Inovatif di Bidang Pengairan – Memiliki semangat kewirausahaan untuk mengembangkan solusi kreatif dan berkelanjutan dalam pengelolaan sumber daya air.
E15: - Konsultan Profesional dan Kompeten – Mampu memberikan layanan konsultasi yang andal, mandiri, dan berbasis keilmuan dalam perencanaan serta pengelolaan infrastruktur pengairan.
E16: - Praktisi Adaptif dan Responsif Global – Mampu beradaptasi terhadap perubahan global serta menjawab kebutuhan masyarakat melalui inovasi dan penerapan teknologi terkini.

Sheet CPL
C3: No | D3: Kode CPL | E3: Komponen | F3: CPL
C4: 1 | D4: CPL-01 | E4: Pengetahuan Umum | F4: Mampu menerapkan pengetahuan matematika, ilmu alam, dan teknologi informasi untuk memahami prinsip-prinsip dasar teknik sumber daya air.
C8: 2 | D8: CPL-02 | E8: Keterampilan Khusus | F8: Mampu merancang sistem jaringan bangunan air dengan mempertimbangkan aspek hukum, ekonomi, lingkungan, sosial, politik, kesehatan dan keselamatan, serta keberlanjutan, serta mengenali dan/atau memanfaatkan potensi sumber daya local dan nasional dengan perspektif global.
C12: 3 | D12: CPL-03 | E12: Keterampilan Khusus | F12: Mampu merancang dan melakukan eksperimen laboratorium maupun pengamatan lapangan serta mampu menganalisis dan menginterpretasikan data untuk mendukung penilaian teknik sumber daya air.
C17: 4 | D17: CPL-04 | E17: Keterampilan Khusus | F17: Mampu mengidentifikasi, merumuskan, menganalisis, dan memecahkan permasalahan kompleks di bidang teknik sumber daya air.
C21: 5 | D21: CPL-05 | E21: Keterampilan Khusus | F21: Mampu menerapkan metode, keterampilan, dan alat rekayasa modern dalam praktik teknik sumber daya air.
C25: 6 | D25: CPL-06 | E25: Keterampilan Umum | F25: Mampu berkomunikasi secara efektif baik secara lisan dan tertulis dalam menyampaikan ide maupun hasil analisis.
C28: 7 | D28: CPL-07 | E28: Keterampilan Umum | F28: Mampu merencanakan, melaksanakan, dan mengevaluasi tugas Teknik sumber daya air sesuai dengan batasan yang tersedia.
C32: 8 | D32: CPL-08 | E32: Keterampilan Umum | F32: Mampu bekerja dalam tim multidisiplin dan multicultural.
C36: 9 | D36: CPL-09 | E36: Sikap | F36: Mampu bertanggung jawab secara profesional dan mematuhi etika profesional terhadap masyarakat dalam merancang dan mengelola infrastruktur Teknik sumber daya air yang aman.
C41: 10 | D41: CPL-10 | E41: Sikap | F41: Mampu menyadari pentingnya pembelajaran sepanjang hayat dengan menerapkan Al Islam Kemuhammadiyahan dan terus mengakses pengetahuan terbaru dan isu yang sejalan dengan perkembangan zaman di bidang sumber daya air.

Sheet IK CPL
C3: No | D3: Kode CPL | E3: Komponen | F3: CPL | G3: Indikator Kinerja
C4: 1 | D4: CPL-01 | E4: Pengetahuan Umum | F4: Mampu menerapkan pengetahuan matematika, ilmu alam, dan teknologi informasi untuk memahami prinsip-prinsip dasar teknik sumber daya air. | G4: Mahasiswa mampu menjelaskan konsep-konsep dasar matematika yang diperlukan dalam analisis sistem sumber daya air.
G5: Mahasiswa mampu menerapkan prinsip fisika dan kimia untuk menjelaskan fenomena air, seperti sifat fluida, perubahan fase, dan interaksi air–material.
G6: Mahasiswa mampu mengaplikasikan konsep ilmu alam untuk memahami proses-proses di lingkungan
G7: Mahasiswa dapat menerapkan pendekatan kuantitatif dalam pemecahan masalah sederhana pada bidang sumber daya air.
C8: 2 | D8: CPL-02 | E8: Keterampilan Khusus | F8: Mampu merancang sistem jaringan bangunan air dengan mempertimbangkan aspek hukum, ekonomi, lingkungan, sosial, politik, kesehatan dan keselamatan, serta keberlanjutan, serta mengenali dan/atau memanfaatkan potensi sumber daya local dan nasional dengan perspektif global. | G8: Mahasiswa mampu mengidentifikasi kebutuhan dan tujuan perancangan sistem jaringan bangunan air berdasarkan kondisi lapangan dan data teknis.
G9: Mahasiswa mampu merancang sistem yang berorientasi pada keberlanjutan dengan mempertimbangkan efisiensi air, energi, dampak jangka panjang, dan ketahanan iklim.
G10: Mahasiswa mampu menghasilkan alternatif desain jaringan bangunan air yang memenuhi persyaratan teknis sekaligus seimbang dalam aspek hukum, ekonomi, lingkungan, sosial, dan politik.
G11: Mahasiswa mampu mempertimbangkan potensi dan standar nasional dalam perencanaan, serta membandingkan dengan praktik dan referensi internasional.
C12: 3 | D12: CPL-03 | E12: Keterampilan Khusus | F12: Mampu merancang dan melakukan eksperimen laboratorium maupun pengamatan lapangan serta mampu menganalisis dan menginterpretasikan data untuk mendukung penilaian teknik sumber daya air. | G12: Mahasiswa mampu melakukan pengukuran lapangan (debit, kualitas air, geometri saluran, permeabilitas tanah, curah hujan, muka air tanah) dengan metode yang benar.
G13: Mahasiswa mampu mengumpulkan dan mencatat data secara akurat menggunakan instrumen pengukuran dan lembar observasi yang sesuai.
G14: Mahasiswa mampu melakukan pengolahan data (statistik dasar, regresi, kalibrasi, analisis grafik) menggunakan software atau alat analisis numerik.
G15: Mahasiswa mampu menginterpretasikan data secara ilmiah untuk menyimpulkan kondisi sistem sumber daya air atau menjawab tujuan penelitian/perancangan.
G16: Mahasiswa mampu menganalisis hasil eksperimen atau pengamatan untuk mengevaluasi fenomena hidrologi atau hidraulika.
C17: 4 | D17: CPL-04 | E17: Keterampilan Khusus | F17: Mampu mengidentifikasi, merumuskan, menganalisis, dan memecahkan permasalahan kompleks di bidang teknik sumber daya air. | G17: Mahasiswa mampu mengidentifikasi permasalahan kompleks terkait hidrologi, hidraulika, pengelolaan air, lingkungan air, atau bangunan air berdasarkan data lapangan, studi literatur, atau fenomena aktual.
G18: Mahasiswa mampu melakukan analisis data dan informasi teknis menggunakan metode kuantitatif maupun kualitatif untuk memahami akar masalah.
G19: Mahasiswa mampu memvalidasi hasil analisis atau pemodelan dengan membandingkan terhadap data lapangan, hasil eksperimen, atau referensi teknis yang tersedia.
G20: Mahasiswa mampu merumuskan masalah secara jelas dan spesifik, termasuk batasan (constraints), asumsi, variabel, dan tujuan pemecahan masalah.
C21: 5 | D21: CPL-05 | E21: Keterampilan Khusus | F21: Mampu menerapkan metode, keterampilan, dan alat rekayasa modern dalam praktik teknik sumber daya air. | G21: Mahasiswa mampu melakukan pemodelan hidrologi dan hidraulika menggunakan metode modern, termasuk simulasi aliran, banjir, jaringan pipa, atau kualitas air.
G22: Mahasiswa mampu menggunakan perangkat lunak teknis seperti HEC-RAS, HEC-HMS, EPANET, SWMM, ArcGIS/QGIS, atau CFD tools untuk menyelesaikan permasalahan sumber daya air.
G23: Mahasiswa mampu memilih metode analisis atau alat rekayasa yang tepat berdasarkan karakteristik permasalahan teknik sumber daya air.
G24: Mahasiswa mampu menerapkan prinsip efisiensi dan efektivitas dalam penggunaan perangkat lunak dan alat rekayasa modern.
C25: 6 | D25: CPL-06 | E25: Keterampilan Umum | F25: Mampu berkomunikasi secara efektif baik secara lisan dan tertulis dalam menyampaikan ide maupun hasil analisis. | G25: Mahasiswa mampu menyusun laporan teknis, makalah, atau dokumen ilmiah dengan struktur yang sistematis, bahasa yang jelas, dan sesuai standar penulisan akademik/profesional.
G26: Mahasiswa mampu menggunakan media komunikasi modern untuk mendukung penyampaian informasi secara efektif.
G27: Mahasiswa mampu menggunakan bahasa Indonesia yang baik dan benar serta bahasa Inggris teknis yang memadai untuk keperluan akademik dan profesional.
C28: 7 | D28: CPL-07 | E28: Keterampilan Umum | F28: Mampu merencanakan, melaksanakan, dan mengevaluasi tugas Teknik sumber daya air sesuai dengan batasan yang tersedia. | G28: Mahasiswa mampu mengidentifikasi tujuan dan ruang lingkup tugas teknik sumber daya air secara jelas sesuai batasan waktu, data, biaya, dan sumber daya.
G29: Mahasiswa mampu menyusun rencana kerja yang sistematis, termasuk penjadwalan, pembagian tugas, dan identifikasi kebutuhan teknis dalam penyelesaian pekerjaan.
G30: Mahasiswa mampu mengevaluasi hasil pekerjaan untuk memastikan kesesuaian dengan standar teknis, tujuan awal, dan batasan yang ditetapkan.
G31: Mahasiswa mampu memberikan rekomendasi perbaikan berdasarkan hasil evaluasi teknis dan pertimbangan praktis.
C32: 8 | D32: CPL-08 | E32: Keterampilan Umum | F32: Mampu bekerja dalam tim multidisiplin dan multicultural. | G32: Mahasiswa mampu bekerja dalam tim dan berkomunikasi secara profesional dengan anggota tim maupun pihak terkait untuk menyelesaikan tugas teknik.
G33: Mahasiswa mampu berperan aktif dalam tim dengan mengambil tanggung jawab yang jelas sesuai kompetensi masing-masing anggota.
G34: Mahasiswa mampu berkontribusi dalam pengambilan keputusan tim secara kolaboratif dan demokratis.
G35: Mahasiswa mampu bekerja sama dengan pihak luar (masyarakat, pemerintah, praktisi) yang memiliki latar belakang sosial dan budaya beragam dalam proyek teknik.
C36: 9 | D36: CPL-09 | E36: Sikap | F36: Mampu bertanggung jawab secara profesional dan mematuhi etika profesional terhadap masyarakat dalam merancang dan mengelola infrastruktur Teknik sumber daya air yang aman. | G36: Mahasiswa mampu menunjukkan etika komunikasi profesional, termasuk kejelasan sumber data, pengakuan kontribusi pihak lain, dan penyampaian informasi secara objektif.
G37: Mahasiswa mampu bekerja secara mandiri maupun dalam tim untuk menyelesaikan tugas sesuai batasan yang ada, sambil menjaga profesionalisme dan etika kerja.
G38: Mahasiswa mampu mematuhi standar, regulasi, dan kode etik profesi seperti peraturan pemerintah, SNI, pedoman teknis, dan standar internasional yang relevan.
G39: Mahasiswa mampu menghindari praktik tidak etis, seperti manipulasi data, plagiarisme, konflik kepentingan, atau penggunaan metode yang tidak aman.
G40: Mahasiswa mampu mempertahankan integritas profesional saat menghadapi tekanan atau pengaruh eksternal dalam proses perancangan atau pengelolaan infrastruktur air.
C41: 10 | D41: CPL-10 | E41: Sikap | F41: Mampu menyadari pentingnya pembelajaran sepanjang hayat dengan menerapkan Al Islam Kemuhammadiyahan dan terus mengakses pengetahuan terbaru dan isu yang sejalan dengan perkembangan zaman di bidang sumber daya air. | G41: Mahasiswa mampu menunjukkan sikap dan perilaku yang mencerminkan nilai-nilai Al Islam Kemuhammadiyahan (kejujuran, amanah, disiplin, tanggung jawab, dan etos kerja) dalam aktivitas akademik dan profesi.
G42: ahasiswa mampu mengikuti perkembangan isu-isu global dan nasional, seperti perubahan iklim, ketahanan air, teknologi digital, dan keberlanjutan.
...

Sheet MK-CPL
C4: No | D4: Mata Kuliah | E4: Kode Mata Kuliah | F4: SKS | G4: CPL
G5: CPL-01 | H5: CPL-02 | I5: CPL-03 | J5: CPL-04 | K5: CPL-05 | L5: CPL-06 | M5: CPL-07 | N5: CPL-08 | O5: CPL-09 | P5: CPL-10
C6: Semester 1
C7: 1 | D7: Pendidikan Agama Islam | E7: AW60910042105 | F7: 2 | G7: 0 | H7: =$B$3*'[1]CPMK & Bobot & SKS'!W8*'[1]Matriks Kurikulum (pts)'!H7 -> 0 | I7: =$B$3*'[1]CPMK & Bobot & SKS'!X8*'[1]Matriks Kurikulum (pts)'!I7 -> 0 | J7: =$B$3*'[1]CPMK & Bobot & SKS'!Y8*'[1]Matriks Kurikulum (pts)'!J7 -> 0 | K7: =$B$3*'[1]CPMK & Bobot & SKS'!Z8*'[1]Matriks Kurikulum (pts)'!K7 -> 0 | L7: =$B$3*'[1]CPMK & Bobot & SKS'!AA8*'[1]Matriks Kurikulum (pts)'!L7 -> 0 | M7: =$B$3*'[1]CPMK & Bobot & SKS'!AB8*'[1]Matriks Kurikulum (pts)'!M7 -> 0 | N7: 33.333333 | O7: 33.333333 | P7: 33.333333
C8: 2 | D8: Pendidikan Pancasila | E8: AW60910042101 | F8: 2 | G8: 0 | H8: 0 | I8: 0 | J8: 0 | K8: 0 | L8: 0 | M8: 0 | N8: 50 | O8: 50 | P8: 0
C9: 3 | D9: Matematika I | E9: CW6220202301 | F9: 3 | G9: 50 | H9: 0 | I9: 0 | J9: 50 | K9: 0 | L9: 0 | M9: 0 | N9: 0 | O9: 0 | P9: 0
C10: 4 | D10: Bahasa Indonesia | E10: AW60910042103 | F10: 2 | G10: 0 | H10: 0 | I10: 0 | J10: 0 | K10: 0 | L10: 100 | M10: 0 | N10: 0 | O10: 0 | P10: 0
C11: 5 | D11: Bahasa Inggris | E11: AW60910042106 | F11: 2 | G11: 0 | H11: 0 | I11: 0 | J11: 0 | K11: 0 | L11: 50 | M11: 0 | N11: 0 | O11: 0 | P11: 50
C12: 6 | D12: Komputer 1 | E12: CW6220202102 | F12: 2 | G12: 50 | H12: 0 | I12: 0 | J12: 0 | K12: 50 | L12: 0 | M12: 0 | N12: 0 | O12: 0 | P12: 0
C13: 7 | D13: Fisika I | E13: CW6220203103 | F13: 3 | G13: 50 | H13: 0 | I13: 0 | J13: 50 | K13: 0 | L13: 0 | M13: 0 | N13: 0 | O13: 0 | P13: 0
C14: 8 | D14: Menggambar Teknik | E14: CW6220202104 | F14: 2 | G14: 0 | H14: 50 | I14: 0 | J14: 0 | K14: 50 | L14: 0 | M14: 0 | N14: 0 | O14: 0 | P14: 0
C15: Semester 2
C16: 1 | D16: AIK II (Peng. Studi Islam & Kemuh. 2) | E16: AW60910042206 | F16: 2 | G16: 0 | H16: 0 | I16: 0 | J16: 0 | K16: 0 | L16: 0 | M16: 0 | N16: 50 | O16: 0 | P16: 50
C17: 2 | D17: Mekanika Teknik I | E17: CW6220202201 | F17: 2 | G17: 50 | H17: 0 | I17: 0 | J17: 50 | K17: 0 | L17: 0 | M17: 0 | N17: 0 | O17: 0 | P17: 0
C18: 3 | D18: Matematika II | E18: CW6220202302 | F18: 3 | G18: 50 | H18: 0 | I18: 0 | J18: 50 | K18: 0 | L18: 0 | M18: 0 | N18: 0 | O18: 0 | P18: 0
C19: 4 | D19: Fisika II | E19: CW6220202303 | F19: 3 | G19: 50 | H19: 0 | I19: 0 | J19: 50 | K19: 0 | L19: 0 | M19: 0 | N19: 0 | O19: 0 | P19: 0
C20: 5 | D20: Hidrolika Dasar | E20: CW6220202204 | F20: 2 | G20: 0 | H20: 50 | I20: 0 | J20: 0 | K20: 50 | L20: 0 | M20: 0 | N20: 0 | O20: 0 | P20: 0
C21: 6 | D21: Pendidikan Kewarganegaraan | E21: AW60910042202 | F21: 2 | G21: 0 | H21: 0 | I21: 0 | J21: 0 | K21: 0 | L21: 0 | M21: 0 | N21: 100 | O21: 0 | P21: 0
C22: 7 | D22: Bahasa Inggris Teknik | E22: CW6220202205 | F22: 2 | G22: 0 | H22: 0 | I22: 0 | J22: 0 | K22: 0 | L22: 50 | M22: 0 | N22: 0 | O22: 0 | P22: 50
C23: 8 | D23: Ilmu Ukur Tanah & Pemetaan | E23: CW6220202206 | F23: 2 | G23: 0 | H23: 50 | I23: 0 | J23: 0 | K23: 50 | L23: 0 | M23: 0 | N23: 0 | O23: 0 | P23: 0
C24: 9 | D24: Sains Kebumian (Hidrologi I) | E24: CW6220202207 | F24: 2 | G24: 25 | H24: 25 | I24: 25 | J24: 0 | K24: 25 | L24: 0 | M24: 0 | N24: 0 | O24: 0 | P24: 0
C25: Semester 3
C26: 1 | D26: AIK III (Aqidah Islam & Kemuh. 3) | E26: AW60910042307 | F26: 2 | G26: 0 | H26: 0 | I26: 0 | J26: 0 | K26: 0 | L26: 0 | M26: 0 | N26: 50 | O26: 0 | P26: 50
C27: 2 | D27: Mekanika Teknik II | E27: CW6220202301 | F27: 2 | G27: 50 | H27: 0 | I27: 0 | J27: 50 | K27: 0 | L27: 0 | M27: 0 | N27: 0 | O27: 0 | P27: 0
C28: 3 | D28: Matematika III | E28: CW6220202302 | F28: 3 | G28: 50 | H28: 0 | I28: 0 | J28: 50 | K28: 0 | L28: 0 | M28: 0 | N28: 0 | O28: 0 | P28: 0
C29: 4 | D29: Kepemimpinan & Kewirausahaan | E29: BW6042303 | F29: 2 | G29: 0 | H29: 0 | I29: 0 | J29: 50 | K29: 0 | L29: 0 | M29: 50 | N29: 0 | O29: 0 | P29: 0
C30: 5 | D30: Hidrolika Terapan | E30: CW6220202303 | F30: 2 | G30: 0 | H30: 50 | I30: 0 | J30: 0 | K30: 50 | L30: 0 | M30: 0 | N30: 0 | O30: 0 | P30: 0
C31: 6 | D31: Etika Profesi | E31: BW6042302 | F31: 2 | G31: 0 | H31: 0 | I31: 0 | J31: 0 | K31: 0 | L31: 0 | M31: 0 | N31: 0 | O31: 100 | P31: 0
C32: 7 | D32: Geologi | E32: CW6220202304 | F32: 2 | G32: 0 | H32: 0 | I32: 50 | J32: 0 | K32: 0 | L32: 50 | M32: 0 | N32: 0 | O32: 0 | P32: 0
C33: 8 | D33: Statistika & Probabilitas | E33: CW6220202305 | F33: 2 | G33: 50 | H33: 0 | I33: 50 | J33: 0 | K33: 0 | L33: 0 | M33: 0 | N33: 0 | O33: 0 | P33: 0
C34: 9 | D34: Hidrologi II | E34: CW6220202306 | F34: 3 | G34: 0 | H34: 50 | I34: 50 | J34: 0 | K34: 0 | L34: 0 | M34: 0 | N34: 0 | O34: 0 | P34: 0
C35: 10 | D35: Pengelolaan Kualitas Jaringan Perpipaan | E35: CW6220202307 | F35: 2 | G35: 0 | H35: 50 | I35: 0 | J35: 0 | K35: 50 | L35: 0 | M35: 0 | N35: 0 | O35: 0 | P35: 0
C36: 11 | D36: Standarisasi Keselamatan Kerja | E36: CW6220202308 | F36: 2 | G36: 0 | H36: 0 | I36: 0 | J36: 0 | K36: 50 | L36: 0 | M36: 0 | N36: 0 | O36: 50 | P36: 0
C37: Semester 4
C38: 1 | D38: AIK IV (Ibadah Khassah & Kemuh. 4) | E38: AW60910042408 | F38: 2 | G38: 0 | H38: 0 | I38: 0 | J38: 0 | K38: 0 | L38: 0 | M38: 0 | N38: 50 | O38: 0 | P38: 50
C39: 2 | D39: Matematika IV | E39: CP6220223401 | F39: 3 | G39: 50 | H39: 0 | I39: 0 | J39: 50 | K39: 0 | L39: 0 | M39: 0 | N39: 0 | O39: 0 | P39: 0
C40: 3 | D40: Mekanika Tanah I | E40: CW6220222401 | F40: 2 | G40: 33.33 | H40: 0 | I40: 33.33 | J40: 0 | K40: 33.33 | L40: 0 | M40: 0 | N40: 0 | O40: 0 | P40: 0
C41: 4 | D41: Ekonomi Teknik | E41: CW6220222402 | F41: 2 | G41: 0 | H41: 50 | I41: 0 | J41: 0 | K41: 0 | L41: 0 | M41: 0 | N41: 50 | O41: 0 | P41: 0
C42: 5 | D42: Teknik Lingkungan & AMDAL | E42: CW6220222403 | F42: 2 | G42: 0 | H42: 0 | I42: 0 | J42: 0 | K42: 50 | L42: 0 | M42: 0 | N42: 0 | O42: 50 | P42: 0
C43: 6 | D43: Kimia | E43: CW6220222404 | F43: 2 | G43: 50 | H43: 0 | I43: 0 | J43: 0 | K43: 50 | L43: 0 | M43: 0 | N43: 0 | O43: 0 | P43: 0
...

Sheet CPMK
C4: No | D4: Mata Kuliah | E4: CPMK
E5: CPMK 1 | F5: Bobot | G5: CPMK 2 | H5: Bobot | I5: CPMK 3 | J5: Bobot | K5: CPMK 4 | L5: Bobot | M5: CPMK 5 | N5: Bobot | O5: CPMK 6 | P5: Bobot | Q5: CPMK 7 | R5: Bobot
C6: Semester 1
C7: 1 | D7: Pendidikan Agama Islam | E7: menjelaskan prinsip-prinsip dasar ajaran Islam terkait etika, akhlak, dan profesionalitas. (CPL 09) | F7: 25 | G7: Mahasiswa mampu menerapkan nilai-nilai keislaman dalam sikap, perilaku akademik, dan pengambilan keputusan. (CPL 10) | H7: 25 | I7: Mahasiswa mampu mengintegrasikan ajaran Islam dengan konteks sosial, budaya, dan profesi teknik pengairan. (CPL 10) | J7: 25 | K7: Mahasiswa mampu menunjukkan komitmen terhadap nilai keberlanjutan, amanah, dan keadilan dalam praktik akademik. (CPL 08) | L7: 25
C8: 2 | D8: Pendidikan Pancasila | E8: Mahasiswa mampu menjelaskan nilai, prinsip, dan sistem etika Pancasila dalam kehidupan berbangsa dan bernegara. (CPL 09) | F8: 25 | G8: Mahasiswa mampu menganalisis persoalan sosial dan profesional menggunakan perspektif etika Pancasila. (CPL 08) | H8: 25 | I8: Mahasiswa mampu menunjukkan sikap integritas, moralitas, dan tanggung jawab sosial dalam aktivitas akademik. (CPL 09) | J8: 25 | K8: Mahasiswa mampu menerapkan nilai-nilai Pancasila sebagai dasar pengambilan keputusan yang adil dan berkeadilan sosial. (CPL 08) | L8: 25
C9: 3 | D9: Matematika I | E9: Menjelaskan konsep limit dan kontinuitas fungsi satu variabel. (CPL 01) | F9: 20 | G9: Menerapkan aturan turunan dalam menyelesaikan persoalan teknik. CPL 01) | H9: 20 | I9: Menganalisis grafik fungsi menggunakan turunan pertama dan kedua. (CPL 04) | J9: 20 | K9: Menghitung integral tak tentu dan tertentu dari fungsi polinomial. (CPL 04) | L9: 20 | M9: Menyusun model matematika sederhana (CPL 04) | N9: 20
C10: 4 | D10: Bahasa Indonesia | E10: Mahasiswa mampu menyusun tulisan ilmiah yang efektif, logis, dan sesuai kaidah bahasa Indonesia akademik. (CPL 06) | F10: 25 | G10: Mahasiswa mampu mengevaluasi penggunaan bahasa dalam laporan, makalah, dan tulisan sumber daya air secara profesional. | H10: 25 | I10: Mahasiswa mampu berkomunikasi secara tertulis untuk menyampaikan ide sumber daya air secara informatif dan etis. | J10: 25 | K10: Mahasiswa mampu menggunakan teknik penulisan akademik untuk mendukung publikasi dan presentasi ilmiah. | L10: 25
C11: 5 | D11: Bahasa Inggris | E11: memahami informasi lisan dalam percakapan sehari-hari dan situasi umum, seperti percakapan sosial, instruksi sederhana, dan dialog akademik dasar (CPL 06) | F11: 25 | G11: membaca dan memahami teks bahasa Inggris umum, seperti artikel pendek, deskripsi, email, dan teks informatif, serta mengidentifikasi ide pokok, detail penting, dan makna kosakata dalam konteks (CPL 06) | H11: 25 | I11: menulis kalimat dan paragraf sederhana dalam bahasa Inggris secara jelas dan koheren (CPL 06) | J11: 25 | K11: berbicara dan berinteraksi dalam bahasa Inggris pada situasi sehari-hari, memperkenalkan diri, memberikan pendapat sederhana, berdiskusi dalam kelompok kecil, dan menyampaikan informasi dasar dengan pelafalan yang dapat dipahami (CPL 10) | L11: 25
C12: 6 | D12: Komputer 1 | E12: menjelaskan komponen dasar sistem komputer, termasuk perangkat keras, perangkat lunak, sistem operasi, penyimpanan data (CPL 01) | F12: 25 | G12: mengoperasikan sistem operasi (Windows/Linux) untuk melakukan manajemen file, pengaturan dasar, instalasi sederhana, dan navigasi perangkat komputer secara efektif (CPL 05) | H12: 25 | I12: menggunakan aplikasi perkantoran dasar (word processing, spreadsheet, dan presentation) untuk membuat dokumen tekstual, tabel data, grafik sederhana, dan presentasi sesuai standar akademik (CPL 05) | J12: 25 | K12: Menggunakan internet, mesin pencari, email, dan platform digital secara efektif serta memahami etika digital, keamanan siber dasar, dan penggunaan teknologi secara bertanggung jawab (CPL 05) | L12: 25
C13: 7 | D13: Fisika I | E13: Menjelaskan konsep kinematika gerak lurus dan gerak melingkar. (CPL 01) | F13: 20 | G13: Menganalisis masalah dinamika menggunakan hukum Newton. (CPL 04) | H13: 20 | I13: Menghitung usaha, energi kinetik, energi potensial, dan penerapannya. (CPL 04) | J13: 20 | K13: Menganalisis tumbukan dan hukum kekekalan momentum. (CPL 04) | L13: 20 | M13: Menjelaskan konsep getaran dan gelombang serta aplikasinya. (CPL 01) | N13: 20
C14: 8 | D14: Menggambar Teknik | E14: Menjelaskan prinsip dan standar dalam gambar teknik. (CPL 02) | F14: 20 | G14: Menggambar proyeksi ortogonal dan tampak potongan bangunan teknik secara manual. (CPL 02) | H14: 20 | I14: Mengoperasikan perangkat lunak CAD (Computer Aided Design) dasar. (CPL 05) | J14: 20 | K14: Menganalisis gambar teknik dan mengoreksi kesalahan gambar. (CPL 02) | L14: 20 | M14: Mempresentasikan hasil gambar teknik secara komunikatif dan profesional. (CPL 05) | N14: 20
C15: Semester 2
C16: 1 | D16: AIK II (Peng. Studi Islam & Kemuh. 2) | E16: Mahasiswa mampu menjelaskan konsep dasar ajaran Islam tentang akidah, ibadah, akhlak, dan moderasi beragama sesuai perspektif Muhammadiyah. (CPL 10) | F16: 25 | G16: Mahasiswa mampu menganalisis nilai-nilai Islam dalam kehidupan sosial, budaya, dan profesional, serta keterkaitannya dengan pembangunan masyarakat. (CPL 10) | H16: 25 | I16: Mahasiswa mampu menerapkan prinsip etika Islam, integritas, dan tanggung jawab sosial dalam aktivitas akademik dan interaksi profesional. (CPL 10) | J16: 25 | K16: Mahasiswa mampu menginterpretasikan nilai dan pemikiran Muhammadiyah dalam merumuskan solusi terhadap isu kemasyarakatan dan tantangan kontemporer. (CPL 08) | L16: 25
C17: 2 | D17: Mekanika Teknik I | E17: Menjelaskan konsep gaya, momen, dan hukum kesetimbangan. (CPL 01) | F17: 20 | G17: Menghitung reaksi perletakan pada balok statis tertentu. (CPL 04) | H17: 20 | I17: Membuat diagram gaya geser dan momen lentur. (CPL 04) | J17: 20 | K17: Menganalisis struktur rangka batang menggunakan metode titik simpul dan metode persamaan. (CPL 04) | L17: 20 | M17: Menyusun laporan teknis analisis gaya struktur sederhana. (CPL 01) | N17: 20
C18: 3 | D18: Matematika II | E18: Menghitung integral tak tentu dan tentu dari fungsi satu dan multi variabel. (CPL 04) | F18: 20 | G18: Menyelesaikan persamaan diferensial orde satu dan orde dua. (CPL 04) | H18: 20 | I18: Menganalisis deret tak hingga dan deret Fourier. (CPL 04) | J18: 20 | K18: Menggunakan transformasi Laplace untuk menyelesaikan persamaan diferensial. (CPL 01) | L18: 20 | M18: Menerapkan konsep matematika lanjut dalam studi kasus teknik pengairan. (CPL 01) | N18: 20
C19: 4 | D19: Fisika II | E19: Menjelaskan konsep dasar listrik statis dan medan listrik. (CPL 01) | F19: 20 | G19: Menjelaskan konsep arus listrik, hukum Ohm, dan rangkaian listrik sederhana. (CPL 01) | H19: 20 | I19: Menganalisis potensial listrik dan energi potensial muatan. (CPL 04) | J19: 20 | K19: Menganalisis konsep kemagnetan dan induksi elektromagnetik. (CPL 04) | L19: 20 | M19: Memahami konsep fisika modern dasar seperti relativitas khusus dan kuantum. (CPL 01) | N19: 20
C20: 5 | D20: Hidrolika Dasar | E20: Menjelaskan sifat dan tekanan fluida dalam kondisi statis. (CPL 02) | F20: 20 | G20: Menerapkan hukum kontinuitas dan energi dalam aliran fluida ideal. (CPL 05) | H20: 20 | I20: Menganalisis kehilangan energi dalam aliran fluida nyata. (CPL 05) | J20: 20 | K20: Menghitung debit aliran pada saluran terbuka dan pipa bertekanan. (CPL 02) | L20: 20 | M20: Menyusun laporan teknis analisis hidrolika dasar (CPL 02) | N20: 20
C21: 6 | D21: Pendidikan Kewarganegaraan (CPL 08) | E21: Mahasiswa mampu menjelaskan prinsip dasar kewarganegaraan, konstitusi, nilai Pancasila, dan sistem demokrasi Indonesia secara komprehensif. | F21: 25 | G21: Mahasiswa mampu menganalisis isu kebangsaan, hak dan kewajiban warga negara, serta tantangan multikulturalisme dalam konteks sosial Indonesia. | H21: 25 | I21: Mahasiswa mampu menunjukkan sikap etis, toleran, bertanggung jawab, serta kesadaran berbangsa dan bernegara dalam kehidupan sosial. | J21: 25 | K21: Mahasiswa mampu menerapkan perspektif kebangsaan dan nilai konstitusional dalam menilai dampak keputusan profesional di bidang sumber daya air dan masyarakat. | L21: 25
C22: 7 | D22: Bahasa Inggris Teknik | E22: Mahasiswa mampu memahami dan menggunakan kosakata teknis sumber daya air dalam bahasa Inggris. (CPL 10) | F22: 25 | G22: Mahasiswa mampu menulis paragraf teknis, deskripsi desain, dan laporan pendek dalam bahasa Inggris akademik. (CPL 06) | H22: 25 | I22: Mahasiswa mampu mempresentasikan ide dasar sumber daya air secara lisan/tertulis menggunakan bahasa Inggris profesional. (CPL 06) | J22: 25 | K22: Mahasiswa mampu membaca, menafsirkan, dan mengutip referensi sumber daya air berbahasa Inggris. (CPL 06) | L22: 25
C23: 8 | D23: Ilmu Ukur Tanah & Pemetaan | E23: Menjelaskan prinsip dasar pengukuran dan pemetaan topografi. (CPL 02) | F23: 20 | G23: Melakukan pengukuran jarak, sudut, dan elevasi menggunakan alat ukur manual dan digital. (CPL 05) | H23: 20 | I23: Menggambar peta topografi dari data hasil pengukuran (CPL 05) | J23: 20 | K23: Mengolah data pengukuran dengan perangkat lunak sederhana. (CPL 05) | L23: 20 | M23: Menyusun laporan hasil pengukuran dan pemetaan topografi. (CPL 05) | N23: 20
C24: 9 | D24: Sains Kebumian (Hidrologi I) | E24: menjelaskan konsep dasar sistem Bumi, termasuk geosfer , proses internal-eksternal Bumi, dan keterkaitannya dengan fenomena alam (CPL 01) | F24: 20 | G24: mengidentifikasi jenis batuan, mineral, tanah, serta struktur geologi berdasarkan karakteristik fisik dan proses pembentukannya, baik melalui pengamatan langsung maupun literatur (CPL 03) | H24: 20 | I24: menganalisis proses geologi (vulkanisme, tektonik, pelapukan, erosi, sedimentasi) dan mendeksripsikan bentuklahan (geomorfologi) serta implikasinya terhadap lingkungan dan pembangunan (CPL 05) | J24: 20 | K24: menjelaskan keterkaitan proses kebumian dengan sumber daya alam (air, mineral, energi) dan potensi kebencanaan geologi seperti gempa, longsor, banjir, serta upaya mitigasinya (CPL 01) | L24: 20 | M24: menerapkan konsep sains kebumian dalam analisis awal untuk perencanaan teknik, termasuk penentuan kondisi tanah, tata air, kestabilan lereng, dan evaluasi lingkungan pada suatu wilayah (CPL 02) | N24: 20
C25: Semester 3
C26: 1 | D26: AIK III (Aqidah Islam & Kemuh. 3) | E26: Mahasiswa mampu menjelaskan prinsip-prinsip aqidah Islam secara benar sesuai Al-Qur’an, Sunnah, dan pandangan Muhammadiyah. | F26: 30 | G26: Mahasiswa mampu menganalisis penerapan akidah dalam pembentukan akhlak, karakter profesional, dan integritas diri di lingkungan akademik dan sosial. | H26: 25 | I26: Mahasiswa mampu menguraikan pemikiran, manhaj tarjih, dan peran Muhammadiyah dalam gerakan pembaruan Islam serta kontribusinya bagi pembangunan masyarakat. | J26: 25 | K26: Mahasiswa mampu menguraikan pemikiran, manhaj tarjih, dan peran Muhammadiyah dalam gerakan pembaruan Islam serta kontribusinya bagi pembangunan masyarakat. | L26: 20
C27: 2 | D27: Mekanika Teknik II | E27: Menganalisis struktur statis tak tentu menggunakan metode analitik (CPL 04) | F27: 20 | G27: Menghitung lendutan pada struktur menggunakan metode energi dan integrasi (CPL 04) | H27: 20 | I27: Menggunakan prinsip superposisi dan analisis numerik pada struktur kompleks (CPL 01) | J27: 20 | K27: Menerapkan metode matriks atau perangkat lunak struktur sederhana (CPL 01) | L27: 20 | M27: Menyusun laporan dan interpretasi hasil analisis struktur teknik sipil (CPL 01) | N27: 20
C28: 3 | D28: Matematika III | E28: Menerapkan konsep analisis vektor dalam masalah teknik (CPL 01) | F28: 20 | G28: Menghitung diferensial vektor (gradien, divergensi, curl) (CPL 04) | H28: 20 | I28: Menyelesaikan persamaan diferensial parsial (PDE) dasar (CPL 04) | J28: 20 | K28: Menerapkan konsep fungsi kompleks dalam analisis teknik (CPL 01) | L28: 20 | M28: Menggunakan transformasi integral (Fourier, Laplace) untuk menyelesaikan masalah teknik (CPL 04) | N28: 20
C29: 4 | D29: Kepemimpinan & Kewirausahaan | E29: Menjelaskan konsep kepemimpinan dan perannya dalam dunia teknik (CPL 07) | F29: 20 | G29: Menganalisis keterampilan interpersonal dan komunikasi dalam tim kerja (CPL 04) | H29: 20 | I29: Menjelaskan prinsip dasar kewirausahaan dan inovasi (CPL07) | J29: 20 | K29: Menyusun rencana bisnis sederhana yang berkelanjutan (CPL 04) | L29: 20 | M29: Mempresentasikan rencana bisnis dan kepemimpinan tim secara profesional (CPL 04) | N29: 20
C30: 5 | D30: Hidrolika Terapan | E30: Menganalisis aliran seragam dan aliran kritis di saluran terbuka (CPL 02) | F30: 20 | G30: Menganalisis aliran tidak seragam menggunakan metode numerik (CPL 02) | H30: 20 | I30: Menerapkan analisis aliran pada struktur pengatur (bendung, pintu air) (CPL 05) | J30: 20 | K30: Menggunakan perangkat lunak untuk simulasi aliran saluran terbuka (CPL 05) | L30: 20 | M30: Menyusun laporan analisis hidrolika terapan berbasis proyek (CPL 05) | N30: 20
C31: 6 | D31: Etika Profesi (CPL 09) | E31: Menjelaskan konsep dasar etika profesi dan peranannya dalam dunia teknik | F31: 20 | G31: Menganalisis kode etik profesi teknik nasional dan internasional | H31: 20 | I31: Mengidentifikasi dilema etika yang umum terjadi dalam praktik teknik | J31: 20 | K31: Menerapkan prinsip etika dalam pengambilan keputusan teknik yang kompleks | L31: 20 | M31: Mempresentasikan pendapat secara profesional dan etis dalam forum akademik | N31: 20
C32: 7 | D32: Geologi | E32: Menjelaskan struktur dan komposisi bumi (CPL 06) | F32: 20 | G32: Mengidentifikasi jenis-jenis batuan dan mineral (CPL 03) | H32: 20 | I32: Menjelaskan proses-proses geologi yang mempengaruhi permukaan bumi (CPL 06) | J32: 20 | K32: Menerapkan pengetahuan geologi dalam perencanaan infrastruktur SDA (CPL 06) | L32: 20 | M32: Menganalisis risiko geologi terhadap konstruksi teknik pengairan (CPL 03) | N32: 20
C33: 8 | D33: Statistika & Probabilitas | E33: Mampu menyajikan data dalam bentuk tabel, grafik, dan diagram (CPL 01) | F33: 20 | G33: Menghitung ukuran pemusatan (mean, median, modus) dan ukuran penyebaran (range, varians, simpangan baku) (CPL 01) | H33: 20 | I33: Menganalisis peluang kejadian menggunakan aturan peluang dasar (CPL 01) | J33: 20 | K33: Menentukan distribusi probabilitas diskrit (binomial, Poisson) dan kontinu (normal) (CPL 01) | L33: 20 | M33: Melakukan uji hipotesis sederhana dan analisis regresi linier (CPL 03) | N33: 20
C34: 9 | D34: Hidrologi II | E34: Menganalisis data hidrologi untuk perhitungan banjir rancangan (CPL 02) | F34: 20 | G34: Menggunakan analisis frekuensi statistik pada data hujan dan debit (CPL 02) | H34: 20 | I34: Membangun model hidrograf satuan dari data hujan dan debit (CPL 02) | J34: 20 | K34: Mengaplikasikan perangkat lunak hidrologi dalam analisis curah hujan dan debit (CPL 03) | L34: 20 | M34: Mengevaluasi hasil analisis hidrologi untuk pengambilan keputusan teknis (CPL 03) | N34: 20
C35: 10 | D35: Pengelolaan Kualitas Jaringan Perpipaan | E35: Menjelaskan parameter kualitas air dan standar baku mutu (CPL 02) | F35: 20 | G35: Menganalisis proses dasar pengolahan air bersih (CPL 02) | H35: 20 | I35: Merancang sistem jaringan perpipaan untuk distribusi air (CPL 02) | J35: 20 | K35: Menerapkan prinsip hidrolika dalam sistem perpipaan bertekanan (CPL 05) | L35: 20 | M35: Menyusun laporan dan presentasi sistem pengolahan dan jaringan distribusi (CPL 05) | N35: 20
C36: 11 | D36: Standarisasi Keselamatan Kerja | E36: Menjelaskan konsep dasar keselamatan dan kesehatan kerja (K3) di proyek konstruksi (CPL 05) | F36: 20 | G36: Menganalisis standar dan regulasi K3 nasional dan internasional (CPL 05) | H36: 20 | I36: Merancang sistem manajemen K3 untuk proyek konstruksi (CPL 09) | J36: 20 | K36: Mengevaluasi penerapan K3 di lapangan melalui studi kasus (CPL 09) | L36: 20 | M36: Menyusun dan mempresentasikan laporan K3 proyek konstruksi (CPL 09) | N36: 20
C37: Semester 4
C38: 1 | D38: AIK IV (Ibadah Khassah & Kemuh. 4) | E38: Mahasiswa mampu menjelaskan prinsip-prinsip fiqh ibadah dan muamalah dalam Islam berdasarkan Al-Qur’an, Sunnah, dan Manhaj Tarjih Muhammadiyah. | F38: 25 | G38: Mahasiswa mampu menganalisis isu-isu ibadah dan muamalah kontemporer (ekonomi, sosial, digital) menggunakan pendekatan tarjih yang rasional dan berbasis dalil. | H38: 25 | I38: Mahasiswa mampu mengevaluasi penerapan nilai ibadah, akhlak, dan muamalah Islami dalam kehidupan pribadi, sosial, dan lingkungan akademik. | J38: 25 | K38: Mahasiswa mampu menerapkan prinsip-prinsip fiqh dan nilai-nilai Kemuhammadiyahan secara etis dan bertanggung jawab dalam pengambilan keputusan akademik dan aktivitas profesional. | L38: 25
C39: 2 | D39: Matematika IV | E39: menjelaskan konsep dasar metode numerik, termasuk galat (error), stabilitas, konvergensi, dan pendekatan numerik terhadap permasalahan matematika teknik (CPL 01) | F39: 20 | G39: menerapkan metode numerik untuk menyelesaikan persamaan nonlinear (bisection, Newton–Raphson) dan sistem persamaan linear (eliminasi Gauss, Gauss–Seidel, Jacobi) serta menganalisis ketepatannya. (CPL 01) | H39: 20 | I39: menggunakan metode interpolasi (Newton, Lagrange), regresi, dan pendekatan kurva untuk memodelkan data teknik serta mengevaluasi hasil pemodelan (CPL 04) | J39: 20 | K39: menghitung turunan dan integral secara numerik menggunakan metode finite difference, aturan trapezoid, Simpson, serta menerapkan metode ini dalam kasus teknik. (CPL 04) | L39: 20 | M39: mengimplementasikan metode numerik menggunakan perangkat lunak atau bahasa pemrograman, mengolah data, serta menyajikan hasil analisis secara akurat (CPL 04) | N39: 20
C40: 3 | D40: Mekanika Tanah I | E40: Menjelaskan konsep kapasitas dukung tanah untuk pondasi dangkal dan dalam. (CPL 01) | F40: 20 | G40: Menganalisis kestabilan lereng alam dan buatan (CPL 05) | H40: 20 | I40: Menghitung tekanan tanah lateral untuk desain dinding penahan tanah (CPL 05) | J40: 20 | K40: Merancang sistem pondasi sesuai kondisi tanah dan beban struktur (CPL 03) | L40: 20 | M40: Menyusun laporan teknis hasil analisis dan desain geoteknik (CPL 03) | N40: 20
C41: 4 | D41: Ekonomi Teknik | E41: Menjelaskan prinsip dasar nilai waktu uang dan aplikasinya dalam proyek teknik (CPL 02) | F41: 20 | G41: Menganalisis kelayakan finansial suatu proyek dengan berbagai metode evaluasi (CPL 02) | H41: 20 | I41: Menerapkan konsep depresiasi dan pengaruh inflasi dalam analisis ekonomi proyek (CPL 02) | J41: 20 | K41: Merancang studi kelayakan sederhana untuk proyek sumber daya air (CPL 02) | L41: 20 | M41: Menyajikan hasil analisis ekonomi dalam bentuk presentasi yang sistematis (CPL 08) | N41: 20
C42: 5 | D42: Teknik Lingkungan & AMDAL | E42: Menjelaskan prinsip dasar teknik lingkungan dan konsep pembangunan berkelanjutan (CPL 05) | F42: 20 | G42: Menganalisis jenis dan sumber pencemaran air, udara, dan tanah (CPL 05) | H42: 20 | I42: Mengenali prosedur dan komponen penyusunan dokumen AMDAL (CPL 05) | J42: 20 | K42: Menyusun kajian dampak lingkungan awal dari suatu proyek SDA (CPL 09) | L42: 20 | M42: Mempresentasikan hasil kajian AMDAL dan berdiskusi secara kritis (CPL 09) | N42: 20
C43: 6 | D43: Kimia | E43: Menjelaskan struktur atom, tabel periodik, dan ikatan kimia (CPL 01) | F43: 20 | G43: Menghitung stoikiometri reaksi kimia (CPL 01) | H43: 20 | I43: Menjelaskan sifat-sifat larutan dan konsentrasinya (CPL 01) | J43: 20 | K43: Menganalisis reaksi kimia yang terjadi di lingkungan perairan (CPL 05) | L43: 20 | M43: Menerapkan konsep kimia dalam pengelolaan kualitas air (CPL 05) | N43: 20
...

Sheet Bobot CPMK
B2: Semester 1 | L2: Semester 5
B4: Mata Kuliah | C4: Muatan CPMK | D4: Bobot CPMK (%) | E4: Muatan CPL | F4: Rasio bobot CMPK per CPL | G4: Bobot CPL | H4: Rasio Bobot CPL | I4: Bobot CPMK (%) | L4: Mata Kuliah | M4: Muatan CPMK | N4: Bobot CPMK (%) | O4: Muatan CPL | P4: Rasio bobot CMPK per CPL | Q4: Bobot CPL | R4: Rasio Bobot CPL | S4: Bobot CPMK (%)
B5: Pendidikan Agama Islam | C5: CPMK 1 | D5: 25 | E5: CPL 09 | F5: =25/33.33 -> 0.75007501 | G5: 33.33 | H5: =33.33/'MK-CPL'!O82 -> 0.08981326 | I5: =F5*H5 -> 0.067366681 | L5: Konstruksi Bendungan I | M5: CPMK 1 | N5: 20 | O5: CPL 02 | P5: =N5/Q5 -> 0.60006001 | Q5: 33.33 | R5: =Q5/'MK-CPL'!H82 -> 0.026747452 | S5: =P5*R5 -> 0.016050076
C6: CPMK 2 | D6: 25 | E6: CPL 10 | F6: =25/33.33 -> 0.75007501 | G6: 33.33 | H6: =G6/'MK-CPL'!P82 -> 0.113625 | I6: =F6*H6 -> 0.085227273 | M6: CPMK 2 | N6: 20 | P6: =N6/Q5 -> 0.60006001 | S6: =P6*R5 -> 0.016050076
C7: CPMK 3 | D7: 25 | F7: =25/33.33 -> 0.75007501 | I7: =F7*H6 -> 0.085227273 | M7: CPMK 3 | N7: 20 | O7: CPL 05 | P7: =N7/Q7 -> 0.60006001 | Q7: 33.33 | R7: =Q7/'MK-CPL'!K82 -> 0.022528947 | S7: =P7*R7 -> 0.01351872
C8: CPMK 4 | D8: 25 | E8: CPL 08 | F8: =25/33.33 -> 0.75007501 | G8: 33.33 | H8: =G8/'MK-CPL'!N82 -> 0.052259946 | I8: =F8*H8 -> 0.039198879 | M8: CPMK 4 | N8: 20 | O8: CPL 02 | P8: =N8/Q8 -> 0.60006001 | Q8: 33.33 | R8: =Q8/'MK-CPL'!H82 -> 0.026747452 | S8: =P8*R8 -> 0.016050076
M9: CPMK 5 | N9: 20 | O9: CPL 09 | P9: =N9/Q9 -> 0.60006001 | Q9: 33.33 | R9: =Q9/'MK-CPL'!O82 -> 0.08981326 | S9: =P9*R9 -> 0.053893345
B11: Mata Kuliah | C11: Muatan CPMK | D11: Bobot CPMK (%) | E11: Muatan CPL | F11: Rasio bobot CMPK per CPL | G11: Bobot CPL | H11: Rasio Bobot CPL | I11: Bobot CPMK (%) | L11: Mata Kuliah | M11: Muatan CPMK | N11: Bobot CPMK (%) | O11: Muatan CPL | P11: Rasio bobot CMPK per CPL | Q11: Bobot CPL | R11: Rasio Bobot CPL | S11: Bobot CPMK (%)
B12: Pendidikan Pancasila | C12: CPMK 1 | D12: 25 | E12: CPL 09 | F12: =D12/50 -> 0.5 | G12: 50 | H12: =G12/'MK-CPL'!O82 -> 0.13473336 | I12: =F12*H12 -> 0.067366681 | L12: Pemindahan Tanah Mekanis | M12: CPMK 1 | N12: 20 | O12: CPL 02 | P12: =N12/Q12 -> 0.4 | Q12: 50 | R12: =Q12/'MK-CPL'!H82 -> 0.040125191 | S12: =P12*R12 -> 0.016050076
C13: CPMK 2 | D13: 25 | E13: CPL 08 | F13: =D13/50 -> 0.5 | G13: 50 | H13: =G13/'MK-CPL'!N82 -> 0.078397759 | I13: =F13*H13 -> 0.039198879 | M13: CPMK 2 | N13: 20 | O13: CPL 05 | P13: =N13/Q12 -> 0.4 | Q13: 50 | R13: =Q13/'MK-CPL'!K82 -> 0.0337968 | S13: =P13*R13 -> 0.01351872
C14: CPMK 3 | D14: 25 | E14: CPL 09 | F14: =D14/50 -> 0.5 | G14: 50 | H14: =G14/'MK-CPL'!O82 -> 0.13473336 | I14: =F14*H14 -> 0.067366681 | M14: CPMK 3 | N14: 20 | O14: CPL 02 | P14: =N14/Q14 -> 0.4 | Q14: 50 | R14: =Q14/'MK-CPL'!H82 -> 0.040125191 | S14: =P14*R14 -> 0.016050076
C15: CPMK 4 | D15: 25 | E15: CPL 08 | F15: =D15/50 -> 0.5 | G15: 50 | H15: =G15/'MK-CPL'!N82 -> 0.078397759 | I15: =F15*H15 -> 0.039198879 | M15: CPMK 4 | N15: 20 | O15: CPL 05 | P15: =N15/Q15 -> 0.4 | Q15: 50 | R15: =Q15/'MK-CPL'!K82 -> 0.0337968 | S15: =P15*R15 -> 0.01351872
M16: CPMK 5 | N16: 20 | P16: =N16/Q15 -> 0.4 | S16: =P16*R15 -> 0.01351872
B18: Mata Kuliah | C18: Muatan CPMK | D18: Bobot CPMK (%) | E18: Muatan CPL | F18: Rasio bobot CMPK per CPL | G18: Bobot CPL | H18: Rasio Bobot CPL | I18: Bobot CPMK (%) | L18: Mata Kuliah | M18: Muatan CPMK | N18: Bobot CPMK (%) | O18: Muatan CPL | P18: Rasio bobot CMPK per CPL | Q18: Bobot CPL | R18: Rasio Bobot CPL | S18: Bobot CPMK (%)
B19: Matematika I | C19: CPMK 1 | D19: 20 | E19: CPL 01 | F19: =D19/50 -> 0.4 | G19: 50 | H19: =G19/'MK-CPL'!G82 -> 0.070148856 | I19: =F19*H19 -> 0.028059542 | L19: Manajemen Air | M19: CPMK 1 | N19: 20 | O19: CPL 07 | P19: =N19/Q19 -> 0.4 | Q19: 50 | R19: =Q19/'MK-CPL'!M82 -> 0.19650998 | S19: =P19*R19 -> 0.078603993
C20: CPMK 2 | D20: 20 | E20: CPL 01 | F20: =D20/50 -> 0.4 | I20: =F20*H19 -> 0.028059542 | M20: CPMK 2 | N20: 20 | P20: =N20/Q19 -> 0.4 | S20: =P20*R19 -> 0.078603993
C21: CPMK 3 | D21: 20 | E21: CPL 04 | F21: =D21/50 -> 0.4 | G21: 50 | H21: =G21/'MK-CPL'!J82 -> 0.087548808 | I21: =F21*H21 -> 0.035019523 | M21: CPMK 3 | N21: 20 | P21: =N21/Q19 -> 0.4 | S21: =P21*R19 -> 0.078603993
C22: CPMK 4 | D22: 20 | E22: CPL 04 | F22: =D22/50 -> 0.4 | I22: =F22*H21 -> 0.035019523 | M22: CPMK 4 | N22: 20 | P22: =N22/Q19 -> 0.4 | S22: =P22*R19 -> 0.078603993
C23: CPMK 5 | D23: 20 | E23: CPL 04 | F23: =D23/50 -> 0.4 | I23: =F23*H21 -> 0.035019523 | M23: CPMK 5 | N23: 20 | O23: CPL 08 | P23: =N23/Q23 -> 0.4 | Q23: 50 | R23: =Q23/'MK-CPL'!N82 -> 0.078397759 | S23: =P23*R23 -> 0.031359104
B26: Mata Kuliah | C26: Muatan CPMK | D26: Bobot CPMK (%) | E26: Muatan CPL | F26: Rasio bobot CMPK per CPL | G26: Bobot CPL | H26: Rasio Bobot CPL | I26: Bobot CPMK (%) | L26: Mata Kuliah | M26: Muatan CPMK | N26: Bobot CPMK (%) | O26: Muatan CPL | P26: Rasio bobot CMPK per CPL | Q26: Bobot CPL | R26: Rasio Bobot CPL | S26: Bobot CPMK (%)
B27: Bahasa Indonesia | C27: CPMK 1 | D27: 25 | E27: CPL 06 | F27: =D27/G27 -> 0.25 | G27: 100 | H27: =G27/'MK-CPL'!L82 -> 0.26946188 | I27: =F27*H27 -> 0.067365471 | L27: Pengembangan Sumber Daya Air | M27: CPMK 1 | N27: 20 | O27: CPL 02 | P27: =N27/Q27 -> 0.4 | Q27: 50 | R27: =Q27/'MK-CPL'!H82 -> 0.040125191 | S27: =P27*R27 -> 0.016050076
C28: CPMK 2 | D28: 25 | F28: =D28/G27 -> 0.25 | I28: =F28*H27 -> 0.067365471 | M28: CPMK 2 | N28: 20 | P28: =N28/Q27 -> 0.4 | S28: =P28*R27 -> 0.016050076
C29: CPMK 3 | D29: 25 | F29: =D29/G27 -> 0.25 | I29: =F29*H27 -> 0.067365471 | M29: CPMK 3 | N29: 20 | P29: =N29/Q27 -> 0.4 | S29: =P29*R27 -> 0.016050076
C30: CPMK 4 | D30: 25 | F30: =D30/G27 -> 0.25 | I30: =F30*H27 -> 0.067365471 | M30: CPMK 4 | N30: 20 | P30: =N30/Q27 -> 0.4 | S30: =P30*R27 -> 0.016050076
M31: CPMK 5 | N31: 20 | O31: CPL 08 | P31: =N31/Q31 -> 0.4 | Q31: 50 | R31: =Q31/'MK-CPL'!N82 -> 0.078397759 | S31: =P31*R31 -> 0.031359104
B33: Mata Kuliah | C33: Muatan CPMK | D33: Bobot CPMK (%) | E33: Muatan CPL | F33: Rasio bobot CMPK per CPL | G33: Bobot CPL | H33: Rasio Bobot CPL | I33: Bobot CPMK (%) | L33: Mata Kuliah | M33: Muatan CPMK | N33: Bobot CPMK (%) | O33: Muatan CPL | P33: Rasio bobot CMPK per CPL | Q33: Bobot CPL | R33: Rasio Bobot CPL | S33: Bobot CPMK (%)
B34: Bahasa Inggris | C34: CPMK 1 | D34: 25 | E34: CPL 06 | F34: =D34/G34 -> 0.5 | G34: 50 | H34: =G34/'MK-CPL'!L82 -> 0.13473094 | I34: =F34*H34 -> 0.067365471 | L34: Perencanaan Drainase Kota | M34: CPMK 1 | N34: 20 | O34: CPL 02 | P34: =N34/Q34 -> 0.4 | Q34: 50 | R34: =Q34/'MK-CPL'!H82 -> 0.040125191 | S34: =P34*R34 -> 0.016050076
C35: CPMK 2 | D35: 25 | F35: =D35/G34 -> 0.5 | I35: =F35*H34 -> 0.067365471 | M35: CPMK 2 | N35: 20 | O35: CPL 05 | P35: =N35/Q34 -> 0.4 | Q35: 50 | R35: =Q35/'MK-CPL'!K82 -> 0.0337968 | S35: =P35*R35 -> 0.01351872
C36: CPMK 3 | D36: 25 | F36: =D36/G34 -> 0.5 | I36: =F36*H34 -> 0.067365471 | M36: CPMK 3 | N36: 20 | P36: =N36/Q34 -> 0.4 | S36: =P36*R35 -> 0.01351872
C37: CPMK 4 | D37: 25 | E37: CPL 10 | F37: =D37/G37 -> 0.5 | G37: 50 | H37: =G37/'MK-CPL'!P82 -> 0.17045455 | I37: =F37*H37 -> 0.085227273 | M37: CPMK 4 | N37: 20 | O37: CPL 02 | P37: =N37/Q34 -> 0.4 | Q37: 50 | R37: =Q37/'MK-CPL'!H82 -> 0.040125191 | S37: =P37*R37 -> 0.016050076
M38: CPMK 5 | N38: 20 | P38: =N38/Q37 -> 0.4 | S38: =P38*R37 -> 0.016050076
B40: Mata Kuliah | C40: Muatan CPMK | D40: Bobot CPMK (%) | E40: Muatan CPL | F40: Rasio bobot CMPK per CPL | G40: Bobot CPL | H40: Rasio Bobot CPL | I40: Bobot CPMK (%) | L40: Mata Kuliah | M40: Muatan CPMK | N40: Bobot CPMK (%) | O40: Muatan CPL | P40: Rasio bobot CMPK per CPL | Q40: Bobot CPL | R40: Rasio Bobot CPL | S40: Bobot CPMK (%)
B41: Komputer I | C41: CPMK 1 | D41: 25 | E41: CPL 01 | F41: =D41/50 -> 0.5 | G41: 50 | H41: =G41/'MK-CPL'!G82 -> 0.070148856 | I41: =F41*H41 -> 0.035074428 | L41: Teknik Pantai | M41: CPMK 1 | N41: 20 | O41: CPL 04 | P41: =N41/Q41 -> 0.4 | Q41: 50 | R41: =Q41/'MK-CPL'!J82 -> 0.087548808 | S41: =P41*R41 -> 0.035019523
C42: CPMK 2 | D42: 25 | E42: CPL 05 | F42: =D42/50 -> 0.5 | G42: 50 | H42: =G42/'MK-CPL'!K82 -> 0.0337968 | I42: =F42*H42 -> 0.0168984 | M42: CPMK 2 | N42: 20 | P42: =N42/Q41 -> 0.4 | S42: =P42*R41 -> 0.035019523
C43: CPMK 3 | D43: 25 | F43: =D43/50 -> 0.5 | I43: =F43*H42 -> 0.0168984 | M43: CPMK 3 | N43: 20 | O43: CPL 05 | P43: =N43/Q41 -> 0.4 | Q43: 50 | R43: =Q43/'MK-CPL'!K82 -> 0.0337968 | S43: =P43*R43 -> 0.01351872
C44: CPMK 4 | D44: 25 | F44: =D44/50 -> 0.5 | I44: =F44*H42 -> 0.0168984 | M44: CPMK 4 | N44: 20 | P44: =N44/Q41 -> 0.4 | S44: =P44*R43 -> 0.01351872
M45: CPMK 5 | N45: 20 | P45: =N45/Q43 -> 0.4 | S45: =P45*R43 -> 0.01351872
B47: Mata Kuliah | C47: Muatan CPMK | D47: Bobot CPMK (%) | E47: Muatan CPL | F47: Rasio bobot CMPK per CPL | G47: Bobot CPL | H47: Rasio Bobot CPL | I47: Bobot CPMK (%) | L47: Mata Kuliah | M47: Muatan CPMK | N47: Bobot CPMK (%) | O47: Muatan CPL | P47: Rasio bobot CMPK per CPL | Q47: Bobot CPL | R47: Rasio Bobot CPL | S47: Bobot CPMK (%)
B48: Fisika I | C48: CPMK 1 | D48: 20 | E48: CPL 01 | F48: =D48/50 -> 0.4 | G48: 50 | H48: =G48/'MK-CPL'!G82 -> 0.070148856 | I48: =F48*H48 -> 0.028059542 | L48: Konstruksi Beton II | M48: CPMK 1 | N48: 20 | O48: CPL 02 | P48: =N48/Q48 -> 0.4 | Q48: 50 | R48: =Q48/'MK-CPL'!H82 -> 0.040125191 | S48: =P48*R48 -> 0.016050076
C49: CPMK 2 | D49: 20 | E49: CPL 04 | F49: =D49/50 -> 0.4 | G49: 50 | H49: =G49/'MK-CPL'!J82 -> 0.087548808 | I49: =F49*H49 -> 0.035019523 | M49: CPMK 2 | N49: 20 | P49: =N49/Q48 -> 0.4 | S49: =P49*R48 -> 0.016050076
...
